#VRML_SIM R2023b utf8

EXTERNPROTO "https://raw.githubusercontent.com/cyberbotics/webots/R2023b/projects/objects/backgrounds/protos/TexturedBackground.proto"
EXTERNPROTO "https://raw.githubusercontent.com/cyberbotics/webots/R2023b/projects/objects/backgrounds/protos/TexturedBackgroundLight.proto"
EXTERNPROTO "https://raw.githubusercontent.com/cyberbotics/webots/R2023b/projects/objects/floors/protos/RectangleArena.proto"

WorldInfo {
}
Viewpoint {
  orientation 0.10673485721121063 0.11308645419879829 -0.9878355754541571 1.4277874982472254
  position 0.22149296400235396 1.9356258448995967 0.6706121718761412
}
TexturedBackground {
}
TexturedBackgroundLight {
}
RectangleArena {
  floorSize 10 10
}
Robot {
  children [
    Solid {
      rotation 0 0 1 3.141593
      children [
        Pose {
          rotation 0 0 1 3.141593
          children [
            DEF base_visual CadShape {
              url [
                "/home/alan/webots/protos/ur5e/visual/base.dae"
              ]
            }
          ]
        }
        HingeJoint {
          jointParameters HingeJointParameters {
            axis 0 0 1
            anchor 0 0 0.1625
          }
          device [
            RotationalMotor {
              name "shoulder_pan_joint"
              maxVelocity 3.141592653589793
              minPosition -6.283185307179586
              maxPosition 6.283185307179586
              maxTorque 150
            }
            PositionSensor {
              name "shoulder_pan_joint_sensor"
            }
          ]
          endPoint Solid {
            translation 0 0 0.1625
            children [
              Pose {
                rotation 0 0 1 3.141593
                children [
                  DEF shoulder_visual CadShape {
                    url [
                      "/home/alan/webots/protos/ur5e/visual/shoulder.dae"
                    ]
                  }
                ]
              }
              HingeJoint {
                jointParameters HingeJointParameters {
                  axis 0 -1 0
                }
                device [
                  RotationalMotor {
                    name "shoulder_lift_joint"
                    maxVelocity 3.141592653589793
                    minPosition -6.283185307179586
                    maxPosition 6.283185307179586
                    maxTorque 150
                  }
                  PositionSensor {
                    name "shoulder_lift_joint_sensor"
                  }
                ]
                endPoint Solid {
                  rotation 1 0 0 1.570796
                  children [
                    Pose {
                      translation 0 0 0.138
                      rotation 0.5773502691896258 -0.5773502691896258 -0.5773502691896258 2.094395
                      children [
                        DEF upperarm_visual CadShape {
                          url [
                            "/home/alan/webots/protos/ur5e/visual/upperarm.dae"
                          ]
                        }
                      ]
                    }
                    HingeJoint {
                      jointParameters HingeJointParameters {
                        axis 0 0 1
                        anchor -0.425 0 0
                      }
                      device [
                        RotationalMotor {
                          name "elbow_joint"
                          maxVelocity 3.141592653589793
                          minPosition -3.141592653589793
                          maxPosition 3.141592653589793
                          maxTorque 150
                        }
                        PositionSensor {
                          name "elbow_joint_sensor"
                        }
                      ]
                      endPoint Solid {
                        translation -0.425 0 0
                        children [
                          Pose {
                            translation 0 0 0.007
                            rotation 0.5773502691896258 -0.5773502691896258 -0.5773502691896258 2.094395
                            children [
                              DEF forearm_visual CadShape {
                                url [
                                  "/home/alan/webots/protos/ur5e/visual/forearm.dae"
                                ]
                              }
                            ]
                          }
                          HingeJoint {
                            jointParameters HingeJointParameters {
                              axis 0 0 1
                              anchor -0.3922 0 0.1333
                            }
                            device [
                              RotationalMotor {
                                name "wrist_1_joint"
                                maxVelocity 3.141592653589793
                                minPosition -6.283185307179586
                                maxPosition 6.283185307179586
                                maxTorque 28
                              }
                              PositionSensor {
                                name "wrist_1_joint_sensor"
                              }
                            ]
                            endPoint Solid {
                              translation -0.3922 0 0.1333
                              children [
                                Pose {
                                  translation 0 0 -0.127
                                  rotation 1 0 0 1.570796
                                  children [
                                    DEF wrist1_visual CadShape {
                                      url [
                                        "/home/alan/webots/protos/ur5e/visual/wrist1.dae"
                                      ]
                                    }
                                  ]
                                }
                                HingeJoint {
                                  jointParameters HingeJointParameters {
                                    axis 0 -1 0
                                    anchor 0 -0.0997 0
                                  }
                                  device [
                                    RotationalMotor {
                                      name "wrist_2_joint"
                                      maxVelocity 3.141592653589793
                                      minPosition -6.283185307179586
                                      maxPosition 6.283185307179586
                                      maxTorque 28
                                    }
                                    PositionSensor {
                                      name "wrist_2_joint_sensor"
                                    }
                                  ]
                                  endPoint Solid {
                                    translation 0 -0.0997 0
                                    rotation 1 0 0 1.570796
                                    children [
                                      Pose {
                                        translation 0 0 -0.0997
                                        children [
                                          DEF wrist2_visual CadShape {
                                            url [
                                              "/home/alan/webots/protos/ur5e/visual/wrist2.dae"
                                            ]
                                          }
                                        ]
                                      }
                                      HingeJoint {
                                        jointParameters HingeJointParameters {
                                          axis 0 1 0
                                          anchor 0 0.0996 0
                                        }
                                        device [
                                          RotationalMotor {
                                            name "wrist_3_joint"
                                            maxVelocity 3.141592653589793
                                            minPosition -6.283185307179586
                                            maxPosition 6.283185307179586
                                            maxTorque 28
                                          }
                                          PositionSensor {
                                            name "wrist_3_joint_sensor"
                                          }
                                        ]
                                        endPoint Solid {
                                          translation 0 0.0996 0
                                          rotation -1 0 0 1.570796
                                          children [
                                            Pose {
                                              translation 0 0 -0.0989
                                              rotation 1 0 0 1.570796
                                              children [
                                                DEF wrist3_visual CadShape {
                                                  url [
                                                    "/home/alan/webots/protos/ur5e/visual/wrist3.dae"
                                                  ]
                                                }
                                              ]
                                            }
                                          ]
                                          name "wrist_3_link"
                                          boundingObject Pose {
                                            translation 0 0 -0.0989
                                            rotation 1 0 0 1.570796
                                            children [
                                              DEF wrist3 Mesh {
                                                url [
                                                  "/home/alan/webots/protos/ur5e/meshes/wrist3.stl"
                                                ]
                                              }
                                            ]
                                          }
                                          physics Physics {
                                            density -1
                                            mass 0.1879
                                            centerOfMass [
                                              0 0 -0.0229
                                            ]
                                            inertiaMatrix [
                                              9.89041e-05 9.89041e-05 0.0001321172
                                              0 0 0
                                            ]
                                          }
                                        }
                                      }
                                    ]
                                    name "wrist_2_link"
                                    boundingObject Pose {
                                      translation 0 0 -0.0997
                                      children [
                                        DEF wrist2 Mesh {
                                          url [
                                            "/home/alan/webots/protos/ur5e/meshes/wrist2.stl"
                                          ]
                                        }
                                      ]
                                    }
                                    physics Physics {
                                      density -1
                                      mass 1.219
                                      centerOfMass [
                                        0 0 0
                                      ]
                                      inertiaMatrix [
                                        0.002559899 0.002559899 0.0021942
                                        0 0 0
                                      ]
                                    }
                                  }
                                }
                              ]
                              name "wrist_1_link"
                              boundingObject Pose {
                                translation 0 0 -0.127
                                rotation 1 0 0 1.570796
                                children [
                                  DEF wrist1 Mesh {
                                    url [
                                      "/home/alan/webots/protos/ur5e/meshes/wrist1.stl"
                                    ]
                                  }
                                ]
                              }
                              physics Physics {
                                density -1
                                mass 1.219
                                centerOfMass [
                                  0 0 0
                                ]
                                inertiaMatrix [
                                  0.002559899 0.002559899 0.0021942
                                  0 0 0
                                ]
                              }
                            }
                          }
                        ]
                        name "forearm_link"
                        boundingObject Pose {
                          translation 0 0 0.007
                          rotation 0.5773502691896258 -0.5773502691896258 -0.5773502691896258 2.094395
                          children [
                            DEF forearm Mesh {
                              url [
                                "/home/alan/webots/protos/ur5e/meshes/forearm.stl"
                              ]
                            }
                          ]
                        }
                        physics Physics {
                          density -1
                          mass 2.275
                          centerOfMass [
                            -0.1961 0 0.007
                          ]
                          inertiaMatrix [
                            0.004095 0.03120936 0.03120936
                            0 1.660275e-18 0
                          ]
                        }
                      }
                    }
                  ]
                  name "upper_arm_link"
                  boundingObject Pose {
                    translation 0 0 0.138
                    rotation 0.5773502691896258 -0.5773502691896258 -0.5773502691896258 2.094395
                    children [
                      DEF upperarm Mesh {
                        url [
                          "/home/alan/webots/protos/ur5e/meshes/upperarm.stl"
                        ]
                      }
                    ]
                  }
                  physics Physics {
                    density -1
                    mass 8.393
                    centerOfMass [
                      -0.2125 0 0.138
                    ]
                    inertiaMatrix [
                      0.0151074 0.1338858 0.1338858
                      0 7.273078e-18 0
                    ]
                  }
                }
              }
            ]
            name "shoulder_link"
            boundingObject Pose {
              rotation 0 0 1 3.141593
              children [
                DEF shoulder Mesh {
                  url [
                    "/home/alan/webots/protos/ur5e/meshes/shoulder.stl"
                  ]
                }
              ]
            }
            physics Physics {
              density -1
              mass 3.7
              centerOfMass [
                0 0 0
              ]
              inertiaMatrix [
                0.0102675 0.0102675 0.00666
                0 0 0
              ]
            }
          }
        }
      ]
      name "base_link_inertia"
      boundingObject Pose {
        rotation 0 0 1 3.141593
        children [
          DEF base Mesh {
            url [
              "/home/alan/webots/protos/ur5e/meshes/base.stl"
            ]
          }
        ]
      }
      physics Physics {
        density -1
        mass 4
        centerOfMass [
          0 0 0
        ]
        inertiaMatrix [
          0.004433332 0.004433332 0.0072
          0 0 0
        ]
      }
    }
  ]
  name "ur5e"
}
